Workbook
Name Approach: 'CMSCore 2.8'!$O$3
Name Approach: 'ONESheet 2.8'!$O$3
Name BillingCountry: 'CMSCore 2.8'!$O$10
Name BillingCountry: 'ONESheet 2.8'!$O$10
Name BillingCountryCurrency: 'CMSCore 2.8'!$O$11
Name BillingCountryCurrency: 'ONESheet 2.8'!$O$11
Name BillingCurrencyTRM: 'CMSCore 2.8'!$X$21
Name BillingCurrencyTRM: 'ONESheet 2.8'!$X$21
Name BusinessCurrency: 'CMSCore 2.8'!$O$13
Name BusinessCurrency: 'ONESheet 2.8'!$O$13
Name BusinessCurrencyTRM: 'CMSCore 2.8'!$O$14
Name BusinessCurrencyTRM: 'ONESheet 2.8'!$O$14
Name CustomerCountry: 'CMSCore 2.8'!$C$3
Name CustomerCountry: 'ONESheet 2.8'!$C$3
Name HoursPerDayTeamBased: 'CMSCore 2.8'!$O$4
Name HoursPerDayTeamBased: 'ONESheet 2.8'!$O$4

Sheet ONESheet 2.8
A1: Scope | N1: Delivery Cost - Internal Use | AC1: Price - Internal Use | AT1: Año 1 Ingreso Mensual | BA1: Año 2 Ingreso Mensual | BH1: Año 3 Ingreso Mensual | BO1: Año 4 Ingreso Mensual | BV1: Año 5 Ingreso Mensual
B2: Fields with * are mandatory for both DealReview and HandOff; ** denotes HandOff-only requirements | N2: Fields with * are mandatory for both DealReview and HandOff; ** denotes HandOff-only requirements
B3: Customer Country * | C3: Noram | N3: Approach * | O3: By Hours | U3: HOURS | V3: =_xlfn.CONCAT("DELIVERY COST (",BillingCountryCurrency,")") -> DELIVERY COST (USD) | W3: =_xlfn.CONCAT("DELIVERY COST (",IF(ISBLANK(BusinessCurrency),"N/A",BusinessCurrency),")") -> DELIVERY COST (N/A) | AD3: =_xlfn.CONCAT("PRICING (",BillingCountryCurrency,")") -> PRICING (USD) | AE3: =_xlfn.CONCAT("PRICING (",IF(ISBLANK(BusinessCurrency),"N/A",BusinessCurrency),")") -> PRICING (N/A) | AF3: + | AG3: =_xlfn.CONCAT("Intercompany (",BillingCountryCurrency,")") -> Intercompany (USD) | AH3: =_xlfn.CONCAT("Intercompany (",IF(ISBLANK(BusinessCurrency),"N/A",BusinessCurrency),")") -> Intercompany (N/A) | AI3: + | AJ3: =_xlfn.CONCAT("WHT (",BillingCountryCurrency,")") -> WHT (USD) | AK3: =_xlfn.CONCAT("WHT (",IF(ISBLANK(BusinessCurrency),"N/A",BusinessCurrency),")") -> WHT (N/A) | AM3: = | AN3: =_xlfn.CONCAT("BUSINESS VOLUME (",BillingCountryCurrency,")") -> BUSINESS VOLUME (USD) | AO3: =_xlfn.CONCAT("BUSINESS VOLUME (",IF(ISBLANK(BusinessCurrency),"N/A",BusinessCurrency),")") -> BUSINESS VOLUME (N/A) | AS3: MILESTONES | AV3: =BillingCountryCurrency -> USD | AW3: =IF(ISBLANK(BusinessCurrency),"N/A",BusinessCurrency) -> N/A | BA3: MILESTONES | BC3: =BillingCountryCurrency -> USD | BD3: =IF(ISBLANK(BusinessCurrency),"N/A",BusinessCurrency) -> N/A | BH3: MILESTONES | BJ3: =BillingCountryCurrency -> USD | BK3: =IF(ISBLANK(BusinessCurrency),"N/A",BusinessCurrency) -> N/A | BO3: MILESTONES | BQ3: =BillingCountryCurrency -> USD | BR3: =IF(ISBLANK(BusinessCurrency),"N/A",BusinessCurrency) -> N/A | BV3: MILESTONES | BX3: =BillingCountryCurrency -> USD | BY3: =IF(ISBLANK(BusinessCurrency),"N/A",BusinessCurrency) -> N/A
B4: Customer Name * | C4: Gama Mobility | N4: =IF(Approach="By Hours", "N/A for ByHours", "Hours/Day") -> N/A for ByHours | O4: 8.1 | T4: SERVICE COSTS | AC4: SERVICE PRICE | AS4: Hito 1 | AU4: 0 | AV4: 0 | AW4: =IFERROR(AV4/BusinessCurrencyTRM,"N/A") -> N/A | BA4: Hito 1 | BB4: 0 | BC4: 0 | BD4: =IFERROR(BC4/BusinessCurrencyTRM,"N/A") -> N/A | BH4: Hito 1 | BI4: 0 | BJ4: 0 | BK4: =IFERROR(BJ4/BusinessCurrencyTRM,"N/A") -> N/A | BO4: Hito 1 | BP4: 0 | BQ4: 0 | BR4: =IFERROR(BQ4/BusinessCurrencyTRM,"N/A") -> N/A | BV4: Hito 1 | BW4: 0 | BX4: 0 | BY4: =IFERROR(BX4/BusinessCurrencyTRM,"N/A") -> N/A
B5: Project Name * | C5: Modern SecOps Envisioning Workshop (Sentinel) | T5: Consultant Team | U5: =IFERROR(SUMIFS(O:O,Y:Y,"varTotalConsultant"),0) -> 91.12 | V5: =IFERROR(SUMIFS(V:V,Y:Y,"varTotalConsultant"),0) -> 3336.8144 | W5: =IFERROR(V5/BusinessCurrencyTRM,"N/A") -> N/A | AC5: Consultant Team | AD5: =IFERROR(SUMIF(Y:Y,"varTotalConsultant",AD:AD),0) -> 5213.8864 | AE5: =IFERROR(AD5/BusinessCurrencyTRM,"N/A") -> N/A | AG5: =IFERROR(SUMIF(Y:Y,"varTotalConsultant",AG:AG),0) -> 0 | AH5: =IFERROR(AG5/BusinessCurrencyTRM,"N/A") -> N/A | AJ5: =IFERROR(SUMIF(Y:Y,"varTotalConsultant",AJ:AJ),0) -> 0 | AK5: =IFERROR(AJ5/BusinessCurrencyTRM,"N/A") -> N/A | AN5: =SUM(AD5,AG5,AJ5) -> 5213.8864 | AO5: =IFERROR(AN5/BusinessCurrencyTRM,"N/A") -> N/A | AS5: Hito 2 | AU5: 0 | AV5: 0 | AW5: =IFERROR(AV5/BusinessCurrencyTRM,"N/A") -> N/A | BA5: Hito 2 | BB5: 0 | BC5: 0 | BD5: =IFERROR(BC5/BusinessCurrencyTRM,"N/A") -> N/A | BH5: Hito 2 | BI5: 0 | BJ5: 0 | BK5: =IFERROR(BJ5/BusinessCurrencyTRM,"N/A") -> N/A | BO5: Hito 2 | BP5: 0 | BQ5: 0 | BR5: =IFERROR(BQ5/BusinessCurrencyTRM,"N/A") -> N/A | BV5: Hito 2 | BW5: 0 | BX5: 0 | BY5: =IFERROR(BX5/BusinessCurrencyTRM,"N/A") -> N/A
B6: Opp ID * | C6: OPP-2026-713922 | N6: Account Manager * | O6: jose.jalabert@softwareone.com | T6: Project Managment | U6: =IFERROR(SUMIFS(O:O,Y:Y,"varTotalPM"),0) -> 18.224 | V6: =IFERROR(SUMIFS(V:V,Y:Y,"varTotalPM"),0) -> 863.8176 | W6: =IFERROR(V6/BusinessCurrencyTRM,"N/A") -> N/A | AC6: Project Managment | AD6: =IFERROR(SUMIF(Y:Y,"varTotalPM",AD:AD),0) -> 1349.8517 | AE6: =IFERROR(AD6/BusinessCurrencyTRM,"N/A") -> N/A | AG6: =IFERROR(SUMIF(Y:Y,"varTotalPM",AG:AG),0) -> 0 | AH6: =IFERROR(AG6/BusinessCurrencyTRM,"N/A") -> N/A | AJ6: =IFERROR(SUMIF(Y:Y,"varTotalPM",AJ:AJ),0) -> 0 | AK6: =IFERROR(AJ6/BusinessCurrencyTRM,"N/A") -> N/A | AN6: =SUM(AD6,AG6,AJ6) -> 1349.8517 | AO6: =IFERROR(AN6/BusinessCurrencyTRM,"N/A") -> N/A | AS6: Hito 3 | AU6: 0 | AV6: 0 | AW6: =IFERROR(AV6/BusinessCurrencyTRM,"N/A") -> N/A | BA6: Hito 3 | BB6: 0 | BC6: 0 | BD6: =IFERROR(BC6/BusinessCurrencyTRM,"N/A") -> N/A | BH6: Hito 3 | BI6: 0 | BJ6: 0 | BK6: =IFERROR(BJ6/BusinessCurrencyTRM,"N/A") -> N/A | BO6: Hito 3 | BP6: 0 | BQ6: 0 | BR6: =IFERROR(BQ6/BusinessCurrencyTRM,"N/A") -> N/A | BV6: Hito 3 | BW6: 0 | BX6: 0 | BY6: =IFERROR(BX6/BusinessCurrencyTRM,"N/A") -> N/A
B7: SWO Job ID / PRJ | N7: Pre-sale in Sale * | O7: claudio.toledo@softwareone.com | T7: Subtotal | U7: =IFERROR(SUM(U5:U6),0) -> 109.344 | V7: =IFERROR(SUM($V$5:$V$6),0) -> 4200.632 | W7: =IFERROR(V7/BusinessCurrencyTRM,"N/A") -> N/A | AC7: Subtotal | AD7: =IFERROR(SUM(AD5:AD6),0) -> 6563.7381 | AE7: =IFERROR(AD7/BusinessCurrencyTRM,"N/A") -> N/A | AG7: =IFERROR(SUM(AG5:AG6),0) -> 0 | AH7: =IFERROR(AG7/BusinessCurrencyTRM,"N/A") -> N/A | AJ7: =IFERROR(SUM(AJ5:AJ6),0) -> 0 | AK7: =IFERROR(AJ7/BusinessCurrencyTRM,"N/A") -> N/A | AN7: =IFERROR(SUM(AN5:AN6),0) -> 6563.7381 | AO7: =IFERROR(AN7/BusinessCurrencyTRM,"N/A") -> N/A | AS7: Hito 4 | AU7: 0 | AV7: 0 | AW7: =IFERROR(AV7/BusinessCurrencyTRM,"N/A") -> N/A | BA7: Hito 4 | BB7: 0 | BC7: 0 | BD7: =IFERROR(BC7/BusinessCurrencyTRM,"N/A") -> N/A | BH7: Hito 4 | BI7: 0 | BJ7: 0 | BK7: =IFERROR(BJ7/BusinessCurrencyTRM,"N/A") -> N/A | BO7: Hito 4 | BP7: 0 | BQ7: 0 | BR7: =IFERROR(BQ7/BusinessCurrencyTRM,"N/A") -> N/A | BV7: Hito 4 | BW7: 0 | BX7: 0 | BY7: =IFERROR(BX7/BusinessCurrencyTRM,"N/A") -> N/A
B8: Main Business Line * | C8: Cibersecurity | N8: Pre-sale in Delivery * | AS8: Hito 5 | AU8: 0 | AV8: 0 | AW8: =IFERROR(AV8/BusinessCurrencyTRM,"N/A") -> N/A | BA8: Hito 5 | BB8: 0 | BC8: 0 | BD8: =IFERROR(BC8/BusinessCurrencyTRM,"N/A") -> N/A | BH8: Hito 5 | BI8: 0 | BJ8: 0 | BK8: =IFERROR(BJ8/BusinessCurrencyTRM,"N/A") -> N/A | BO8: Hito 5 | BP8: 0 | BQ8: 0 | BR8: =IFERROR(BQ8/BusinessCurrencyTRM,"N/A") -> N/A | BV8: Hito 5 | BW8: 0 | BX8: 0 | BY8: =IFERROR(BX8/BusinessCurrencyTRM,"N/A") -> N/A
B9: Funding * | T9: OTHER COSTS | AC9: OTHER PRICES | AS9: Hito 6 | AU9: 0 | AV9: 0 | AW9: =IFERROR(AV9/BusinessCurrencyTRM,"N/A") -> N/A | BA9: Hito 6 | BB9: 0 | BC9: 0 | BD9: =IFERROR(BC9/BusinessCurrencyTRM,"N/A") -> N/A | BH9: Hito 6 | BI9: 0 | BJ9: 0 | BK9: =IFERROR(BJ9/BusinessCurrencyTRM,"N/A") -> N/A | BO9: Hito 6 | BP9: 0 | BQ9: 0 | BR9: =IFERROR(BQ9/BusinessCurrencyTRM,"N/A") -> N/A | BV9: Hito 6 | BW9: 0 | BX9: 0 | BY9: =IFERROR(BX9/BusinessCurrencyTRM,"N/A") -> N/A
B10: OPP Type * | N10: Billing Country * | O10: =CustomerCountry -> Noram | T10: Risks | V10: =IFERROR(SUMIF(Y:Y,"varTotalRisks",V:V),0) -> 0 | W10: =IFERROR(V10/BusinessCurrencyTRM,"N/A") -> N/A | AC10: Risks | AD10: =IFERROR(SUMIF(Y:Y,"varTotalRisks",AD:AD),0) -> 0 | AE10: =IFERROR(AD10/BusinessCurrencyTRM,"N/A") -> N/A | AG10: =IFERROR(SUMIF(Y:Y,"varTotalRisks",AG:AG),0) -> 0 | AH10: =IFERROR(AG10/BusinessCurrencyTRM,"N/A") -> N/A | AJ10: =IFERROR(SUMIF(Y:Y,"varTotalRisks",AJ:AJ),0) -> 0 | AK10: =IFERROR(AJ10/BusinessCurrencyTRM,"N/A") -> N/A | AN10: =SUM(AD10,AG10,AJ10) -> 0 | AO10: =IFERROR(AN10/BusinessCurrencyTRM,"N/A") -> N/A | AS10: Hito 7 | AU10: 0 | AV10: 0 | AW10: =IFERROR(AV10/BusinessCurrencyTRM,"N/A") -> N/A | BA10: Hito 7 | BB10: 0 | BC10: 0 | BD10: =IFERROR(BC10/BusinessCurrencyTRM,"N/A") -> N/A | BH10: Hito 7 | BI10: 0 | BJ10: 0 | BK10: =IFERROR(BJ10/BusinessCurrencyTRM,"N/A") -> N/A | BO10: Hito 7 | BP10: 0 | BQ10: 0 | BR10: =IFERROR(BQ10/BusinessCurrencyTRM,"N/A") -> N/A | BV10: Hito 7 | BW10: 0 | BX10: 0 | BY10: =IFERROR(BX10/BusinessCurrencyTRM,"N/A") -> N/A
N11: Billing Country Currency * | O11: =INDEX(Paramenters!$C$28:$C$85,MATCH(BillingCountry,Paramenters!$A$28:$A$85,0)) -> USD | T11: Pay Rise | V11: =IFERROR(SUMIF(Y:Y,"varTotalPayRise",V:V),0) -> 0 | W11: =IFERROR(V11/BusinessCurrencyTRM,"N/A") -> N/A | AC11: Salary Increase | AD11: =IFERROR(SUMIF(Y:Y,"varTotalPayRise",AD:AD),0) -> 0 | AE11: =IFERROR(AD11/BusinessCurrencyTRM,"N/A") -> N/A | AG11: =IFERROR(SUMIF(Y:Y,"varTotalPayRise",AG:AG),0) -> 0 | AH11: =IFERROR(AG11/BusinessCurrencyTRM,"N/A") -> N/A | AJ11: =IFERROR(SUMIF(Y:Y,"varTotalPayRise",AJ:AJ),0) -> 0 | AK11: =IFERROR(AJ11/BusinessCurrencyTRM,"N/A") -> N/A | AN11: =SUM(AD11,AG11,AJ11) -> 0 | AO11: =IFERROR(AN11/BusinessCurrencyTRM,"N/A") -> N/A | AS11: Hito 8 | AU11: 0 | AV11: 0 | AW11: =IFERROR(AV11/BusinessCurrencyTRM,"N/A") -> N/A | BA11: Hito 8 | BB11: 0 | BC11: 0 | BD11: =IFERROR(BC11/BusinessCurrencyTRM,"N/A") -> N/A | BH11: Hito 8 | BI11: 0 | BJ11: 0 | BK11: =IFERROR(BJ11/BusinessCurrencyTRM,"N/A") -> N/A | BO11: Hito 8 | BP11: 0 | BQ11: 0 | BR11: =IFERROR(BQ11/BusinessCurrencyTRM,"N/A") -> N/A | BV11: Hito 8 | BW11: 0 | BX11: 0 | BY11: =IFERROR(BX11/BusinessCurrencyTRM,"N/A") -> N/A
B12: SKUs Business Line SWO * | C12: SKUs OneSales Descripcion * | T12: Products | V12: =IFERROR(SUMIF(Y:Y,"varTotalProducts",V:V),0) -> 0 | W12: =IFERROR(V12/BusinessCurrencyTRM,"N/A") -> N/A | AC12: Products | AD12: =IFERROR(SUMIF(Y:Y,"varTotalProducts",AD:AD),0) -> 0 | AE12: =IFERROR(AD12/BusinessCurrencyTRM,"N/A") -> N/A | AG12: =IFERROR(SUMIF(Y:Y,"varTotalProducts",AG:AG),0) -> 0 | AH12: =IFERROR(AG12/BusinessCurrencyTRM,"N/A") -> N/A | AJ12: =IFERROR(SUMIF(Y:Y,"varTotalProducts",AJ:AJ),0) -> 0 | AK12: =IFERROR(AJ12/BusinessCurrencyTRM,"N/A") -> N/A | AN12: =SUM(AD12,AG12,AJ12) -> 0 | AO12: =IFERROR(AN12/BusinessCurrencyTRM,"N/A") -> N/A | AS12: Hito 9 | AU12: 0 | AV12: 0 | AW12: =IFERROR(AV12/BusinessCurrencyTRM,"N/A") -> N/A | BA12: Hito 9 | BB12: 0 | BC12: 0 | BD12: =IFERROR(BC12/BusinessCurrencyTRM,"N/A") -> N/A | BH12: Hito 9 | BI12: 0 | BJ12: 0 | BK12: =IFERROR(BJ12/BusinessCurrencyTRM,"N/A") -> N/A | BO12: Hito 9 | BP12: 0 | BQ12: 0 | BR12: =IFERROR(BQ12/BusinessCurrencyTRM,"N/A") -> N/A | BV12: Hito 9 | BW12: 0 | BX12: 0 | BY12: =IFERROR(BX12/BusinessCurrencyTRM,"N/A") -> N/A
N13: Business Currency | T13: Vendors | V13: =IFERROR(SUMIF(Y:Y,"varTotalVAR",V:V),0) -> 0 | W13: =IFERROR(V13/BusinessCurrencyTRM,"N/A") -> N/A | AC13: Vendors | AD13: =IFERROR(SUMIF(Y:Y,"varTotalVAR",AD:AD),0) -> 0 | AE13: =IFERROR(AD13/BusinessCurrencyTRM,"N/A") -> N/A | AG13: =IFERROR(SUMIF(Y:Y,"varTotalVAR",AG:AG),0) -> 0 | AH13: =IFERROR(AG13/BusinessCurrencyTRM,"N/A") -> N/A | AJ13: =IFERROR(SUMIF(Y:Y,"varTotalVAR",AJ:AJ),0) -> 0 | AK13: =IFERROR(AJ13/BusinessCurrencyTRM,"N/A") -> N/A | AN13: =SUM(AD13,AG13,AJ13) -> 0 | AO13: =IFERROR(AN13/BusinessCurrencyTRM,"N/A") -> N/A | AS13: Hito 10 | AU13: 0 | AV13: 0 | AW13: =IFERROR(AV13/BusinessCurrencyTRM,"N/A") -> N/A | BA13: Hito 10 | BB13: 0 | BC13: 0 | BD13: =IFERROR(BC13/BusinessCurrencyTRM,"N/A") -> N/A | BH13: Hito 10 | BI13: 0 | BJ13: 0 | BK13: =IFERROR(BJ13/BusinessCurrencyTRM,"N/A") -> N/A | BO13: Hito 10 | BP13: 0 | BQ13: 0 | BR13: =IFERROR(BQ13/BusinessCurrencyTRM,"N/A") -> N/A | BV13: Hito 10 | BW13: 0 | BX13: 0 | BY13: =IFERROR(BX13/BusinessCurrencyTRM,"N/A") -> N/A
N14: Currency Exchange Rate | T14: Insurances | V14: =IFERROR(SUMIF(Y:Y,"varTotalInsurances",V:V),0) -> 0 | W14: =IFERROR(V14/BusinessCurrencyTRM,"N/A") -> N/A | AC14: Insurances | AD14: =IFERROR(SUMIF(Y:Y,"varTotalInsurances",AD:AD),0) -> 0 | AE14: =IFERROR(AD14/BusinessCurrencyTRM,"N/A") -> N/A | AG14: =IFERROR(SUMIF(Y:Y,"varTotalInsurances",AG:AG),0) -> 0 | AH14: =IFERROR(AG14/BusinessCurrencyTRM,"N/A") -> N/A | AJ14: =IFERROR(SUMIF(Y:Y,"varTotalInsurances",AJ:AJ),0) -> 0 | AK14: =IFERROR(AJ14/BusinessCurrencyTRM,"N/A") -> N/A | AN14: =SUM(AD14,AG14,AJ14) -> 0 | AO14: =IFERROR(AN14/BusinessCurrencyTRM,"N/A") -> N/A | AS14: Hito 11 | AU14: 0 | AV14: 0 | AW14: =IFERROR(AV14/BusinessCurrencyTRM,"N/A") -> N/A | BA14: Hito 11 | BB14: 0 | BC14: 0 | BD14: =IFERROR(BC14/BusinessCurrencyTRM,"N/A") -> N/A | BH14: Hito 11 | BI14: 0 | BJ14: 0 | BK14: =IFERROR(BJ14/BusinessCurrencyTRM,"N/A") -> N/A | BO14: Hito 11 | BP14: 0 | BQ14: 0 | BR14: =IFERROR(BQ14/BusinessCurrencyTRM,"N/A") -> N/A | BV14: Hito 11 | BW14: 0 | BX14: 0 | BY14: =IFERROR(BX14/BusinessCurrencyTRM,"N/A") -> N/A
N15: Exchange Rate Request Date | T15: Others | V15: =IFERROR(SUMIF(Y:Y,"varTotalOthers",V:V),0) -> 0 | W15: =IFERROR(V15/BusinessCurrencyTRM,"N/A") -> N/A | AC15: Others | AD15: =IFERROR(SUMIF(Y:Y,"varTotalOthers",AD:AD),0) -> 0 | AE15: =IFERROR(AD15/BusinessCurrencyTRM,"N/A") -> N/A | AG15: =IFERROR(SUMIF(Y:Y,"varTotalOthers",AG:AG),0) -> 0 | AH15: =IFERROR(AG15/BusinessCurrencyTRM,"N/A") -> N/A | AJ15: =IFERROR(SUMIF(Y:Y,"varTotalOthers",AJ:AJ),0) -> 0 | AK15: =IFERROR(AJ15/BusinessCurrencyTRM,"N/A") -> N/A | AN15: =SUM(AD15,AG15,AJ15) -> 0 | AO15: =IFERROR(AN15/BusinessCurrencyTRM,"N/A") -> N/A | AS15: Hito 12 | AU15: 0 | AV15: 0 | AW15: =IFERROR(AV15/BusinessCurrencyTRM,"N/A") -> N/A | BA15: Hito 12 | BB15: 0 | BC15: 0 | BD15: =IFERROR(BC15/BusinessCurrencyTRM,"N/A") -> N/A | BH15: Hito 12 | BI15: 0 | BJ15: 0 | BK15: =IFERROR(BJ15/BusinessCurrencyTRM,"N/A") -> N/A | BO15: Hito 12 | BP15: 0 | BQ15: 0 | BR15: =IFERROR(BQ15/BusinessCurrencyTRM,"N/A") -> N/A | BV15: Hito 12 | BW15: 0 | BX15: 0 | BY15: =IFERROR(BX15/BusinessCurrencyTRM,"N/A") -> N/A
O16: =IF(ISBLANK(BusinessCurrency),"","* Request the official TRM/RMR from the financial area and/or official url in each billing country") | T16: Subtotal | V16: =IFERROR(SUM(V10:V15),0) -> 0 | W16: =IFERROR(V16/BusinessCurrencyTRM,"N/A") -> N/A | AC16: Subtotal | AD16: =IFERROR(SUM(AD10:AD15),0) -> 0 | AE16: =IFERROR(AD16/BusinessCurrencyTRM,"N/A") -> N/A | AG16: =IFERROR(SUM(AG10:AG15),0) -> 0 | AH16: =IFERROR(AG16/BusinessCurrencyTRM,"N/A") -> N/A | AJ16: =IFERROR(SUM(AJ10:AJ15),0) -> 0 | AK16: =IFERROR(AJ16/BusinessCurrencyTRM,"N/A") -> N/A | AN16: =IFERROR(SUM(AN10:AN15),0) -> 0 | AO16: =IFERROR(AN16/BusinessCurrencyTRM,"N/A") -> N/A | AU16: =SUM(AU4:AU15) -> 0 | AV16: =SUM(AV4:AV15) -> 0 | AW16: =SUM(AW4:AW15) -> 0 | BB16: =SUM(BB4:BB15) -> 0 | BC16: =SUM(BC4:BC15) -> 0 | BD16: =SUM(BD4:BD15) -> 0 | BI16: =SUM(BI4:BI15) -> 0 | BJ16: =SUM(BJ4:BJ15) -> 0 | BK16: =SUM(BK4:BK15) -> 0 | BP16: =SUM(BP4:BP15) -> 0 | BQ16: =SUM(BQ4:BQ15) -> 0 | BR16: =SUM(BR4:BR15) -> 0 | BW16: =SUM(BW4:BW15) -> 0 | BX16: =SUM(BX4:BX15) -> 0 | BY16: =SUM(BY4:BY15) -> 0
B17: Deal Comments
B18: Market B | AV18: =BillingCountryCurrency -> USD | AW18: =IF(ISBLANK(BusinessCurrency),"N/A",BusinessCurrency) -> N/A
AC19: SUBTOTAL | AD19: =SUM(AD7,AD16) -> 6563.7381 | AE19: =IFERROR(AD19/BusinessCurrencyTRM,"N/A") -> N/A | AG19: =SUM(AG7,AG16) -> 0 | AH19: =IFERROR(AG19/BusinessCurrencyTRM,"N/A") -> N/A | AJ19: =SUM(AJ7,AJ16) -> 0 | AK19: =IFERROR(AJ19/BusinessCurrencyTRM,"N/A") -> N/A | AN19: =SUM(AN7,AN16) -> 6563.7381 | AO19: =IFERROR(AN19/BusinessCurrencyTRM,"N/A") -> N/A | AS19: BUSINESS PRICE | AV19: =AN21 -> 6499.9981 | AW19: =IFERROR(AV19/BusinessCurrencyTRM,"N/A") -> N/A
AC20: ADDITIONAL GP | AD20: -63.74 | AE20: =IFERROR(AD20/BusinessCurrencyTRM,"N/A") -> N/A | AG20: 0 | AH20: =IFERROR(AG20/BusinessCurrencyTRM,"N/A") -> N/A | AJ20: 0 | AK20: =IFERROR(AJ20/BusinessCurrencyTRM,"N/A") -> N/A | AN20: =SUM(AD20,AG20,AJ20) -> -63.74 | AO20: =IFERROR(AN20/BusinessCurrencyTRM,"N/A") -> N/A | AS20: DELIVERY COST | AV20: =SUM($V$21,$AG$21,$AJ$21) -> 4200.632 | AW20: =IFERROR(AV20/BusinessCurrencyTRM,"N/A") -> N/A
N21: =IF(CustomerCountry="Colombia","Impuesto de Timbre","") | O21: =IF(CustomerCountry="Colombia","Aplica a nuevos contratos donde la cuantia supera los 6.000 UVT (COP 298.794.000)","") | T21: TOTAL COSTS | V21: =V7+V16 -> 4200.632 | W21: =IFERROR(V21/BusinessCurrencyTRM,"N/A") -> N/A | X21: =INDEX(Paramenters!$D$28:$D$85,MATCH(BillingCountryCurrency,Paramenters!$C$28:$C$85,0)) -> 1.2788018 | Y21: BillingCurrencyTRM | AC21: TOTAL PRICE | AD21: =SUM(AD19:AD20) -> 6499.9981 | AE21: =IFERROR(AD21/BusinessCurrencyTRM,"N/A") -> N/A | AG21: =SUM(AG19:AG20) -> 0 | AH21: =IFERROR(AG21/BusinessCurrencyTRM,"N/A") -> N/A | AJ21: =SUM(AJ19:AJ20) -> 0 | AK21: =IFERROR(AJ21/BusinessCurrencyTRM,"N/A") -> N/A | AN21: =SUM(AN19:AN20) -> 6499.9981 | AO21: =IFERROR(AN21/BusinessCurrencyTRM,"N/A") -> N/A | AS21: % CONTRIBUTION MARGIN | AV21: =IFERROR(1-AV20/AV19,0) -> 0.35374873
B24: (Note 1) To add new phases/stages/blocks, it is recommended to use the phase/stage/block called "Phase_Name_7" which does not have fixed references and allows maintaining cell relationships.
B26: MCI/EA(CSI) PROGRAM: Modern SecOps Envisioning Workshop (Sentinel)
N27: PROJECT WEIGHT BY PHASE | O27: Hours | P27: Percentage (%) | U27: COSTS BY PHASE | V27: =_xlfn.CONCAT("DELIVERY COST (",BillingCountryCurrency,")") -> DELIVERY COST (USD) | W27: =_xlfn.CONCAT("DELIVERY COST (",IF(ISBLANK(BusinessCurrency),"N/A",BusinessCurrency),")") -> DELIVERY COST (N/A) | AC27: PRICE BY PHASE | AD27: =_xlfn.CONCAT("PRICING (",BillingCountryCurrency,")") -> PRICING (USD) | AE27: =_xlfn.CONCAT("PRICING (",IF(ISBLANK(BusinessCurrency),"N/A",BusinessCurrency),")") -> PRICING (N/A) | AF27: + | AG27: =_xlfn.CONCAT("Intercompany (",BillingCountryCurrency,")") -> Intercompany (USD) | AH27: =_xlfn.CONCAT("Intercompany (",IF(ISBLANK(BusinessCurrency),"N/A",BusinessCurrency),")") -> Intercompany (N/A) | AI27: + | AJ27: =_xlfn.CONCAT("WHT (",BillingCountryCurrency,")") -> WHT (USD) | AK27: =_xlfn.CONCAT("WHT (",IF(ISBLANK(BusinessCurrency),"N/A",BusinessCurrency),")") -> WHT (N/A) | AM27: = | AN27: =_xlfn.CONCAT("SUBTOTAL PRICE (",BillingCountryCurrency,")") -> SUBTOTAL PRICE (USD) | AO27: =_xlfn.CONCAT("SUBTOTAL PRICE (",IF(ISBLANK(BusinessCurrency),"N/A",BusinessCurrency),")") -> SUBTOTAL PRICE (N/A) | AS27: SUMMARY BY PHASE
N28: Consultant Team: | O28: =SUMIF($P42:$P71,"<>*Project Management*",$T42:$T71) -> 91.12 | P28: =IFERROR(O28/O31,0) -> 0.76917882 | U28: Consultant Team | V28: =SUMIF(P42:P71,"<>*Project Management*",W42:W71) -> 3336.8144 | W28: =IFERROR(V28/BusinessCurrencyTRM,"N/A") -> N/A | Y28: varTotalConsultant | AC28: Consultant Team | AD28: =SUMIF(P42:P71,"<>*Project Management*",AD42:AD71) -> 5213.8864 | AE28: =IFERROR(AD28/BusinessCurrencyTRM,"N/A") -> N/A | AG28: =SUMIF(P42:P71,"<>*Project Management*",AH42:AH71) -> 0 | AH28: =IFERROR(AG28/BusinessCurrencyTRM,"N/A") -> N/A | AJ28: =SUMIF(P42:P71,"<>*Project Management*",AK42:AK71) -> 0 | AK28: =IFERROR(AJ28/BusinessCurrencyTRM,"N/A") -> N/A | AN28: =SUM(AD28,AG28,AJ28) -> 5213.8864 | AO28: =IFERROR(AN28/BusinessCurrencyTRM,"N/A") -> N/A | AS28: % Margin a Sold * | AV28: 0.36
N29: Project Managment: | O29: =SUMIF($P42:$P71,"=*Project Management*",$T42:T71) -> 18.224 | P29: =IFERROR(O29/O31,0) -> 0.15383576 | U29: Project Managment | V29: =SUMIF(P42:P71,"=*Project Management*",W42:W71) -> 863.8176 | W29: =IFERROR(V29/BusinessCurrencyTRM,"N/A") -> N/A | Y29: varTotalPM | AC29: Project Managment | AD29: =SUMIF(P42:P71,"=*Project Management*",AD42:AD71) -> 1349.8517 | AE29: =IFERROR(AD29/BusinessCurrencyTRM,"N/A") -> N/A | AG29: =SUMIF(P42:P71,"=*Project Management*",AH42:AH71) -> 0 | AH29: =IFERROR(AG29/BusinessCurrencyTRM,"N/A") -> N/A | AJ29: =SUMIF(P42:P71,"=*Project Management*",AK42:AK71) -> 0 | AK29: =IFERROR(AJ29/BusinessCurrencyTRM,"N/A") -> N/A | AN29: =SUM(AD29,AG29,AJ29) -> 1349.8517 | AO29: =IFERROR(AN29/BusinessCurrencyTRM,"N/A") -> N/A | AS29: % Contribution Margin | AV29: =IFERROR(1-AV31/AV32,0) -> 0.36002443
N30: Risk / Extra Effort: | O30: =IF(Approach="Team-Based",SUM(O28:O29)*$O33,$J40-$G40) -> 9.12 | P30: =IFERROR(O30/O31,0) -> 0.076985413 | U30: Subtotal | V30: =SUM(V28:V29) -> 4200.632 | W30: =IFERROR(V30/BusinessCurrencyTRM,"N/A") -> N/A | AC30: Subtotal | AD30: =SUM(AD28:AD29) -> 6563.7381 | AE30: =IFERROR(AD30/BusinessCurrencyTRM,"N/A") -> N/A | AG30: =SUM(AG28:AG29) -> 0 | AH30: =IFERROR(AG30/BusinessCurrencyTRM,"N/A") -> N/A | AJ30: =SUM(AJ28:AJ29) -> 0 | AK30: =IFERROR(AJ30/BusinessCurrencyTRM,"N/A") -> N/A | AN30: =SUM(AD30,AG30,AJ30) -> 6563.7381 | AO30: =IFERROR(AN30/BusinessCurrencyTRM,"N/A") -> N/A | AV30: =BillingCountryCurrency -> USD | AW30: =IF(ISBLANK(BusinessCurrency),"N/A",BusinessCurrency) -> N/A
N31: Total | O31: =SUM(O28:O30) -> 118.464 | P31: =SUM(P28:P30) -> 1 | U31: Risks | V31: =ROUNDUP(V30*O33,2) -> 0 | W31: =IFERROR(V31/BusinessCurrencyTRM,"N/A") -> N/A | Y31: varTotalRisks | AC31: Risks | AD31: =ROUNDUP(V31/(1-$AV$28),2) -> 0 | AE31: =IFERROR(AD31/BusinessCurrencyTRM,"N/A") -> N/A | AG31: =IFERROR(V31*MAX(AG42:AG71),0) -> 0 | AH31: =IFERROR(AG31/BusinessCurrencyTRM,"N/A") -> N/A | AJ31: =IFERROR(SUM(V31,AG31)*MAX(AJ42:AJ71),0) -> 0 | AK31: =IFERROR(AJ31/BusinessCurrencyTRM,"N/A") -> N/A | AN31: =SUM(AD31,AG31,AJ31) -> 0 | AO31: =IFERROR(AN31/BusinessCurrencyTRM,"N/A") -> N/A | AS31: Phase Cost | AV31: =SUM(V37,AG37,AJ37) -> 4200.632 | AW31: =IFERROR(AV31/BusinessCurrencyTRM,"N/A") -> N/A
U32: Pay Rise | V32: =IFERROR(SUMIF(PayRise!A:A,B26,PayRise!J:J),0) -> 0 | W32: =IFERROR(V32/BusinessCurrencyTRM,"N/A") -> N/A | Y32: varTotalPayRise | AC32: Pay Rise | AD32: =IFERROR(SUMIF(PayRise!A:A,B26,PayRise!K:K),0) -> 0 | AE32: =IFERROR(AD32/BusinessCurrencyTRM,"N/A") -> N/A | AG32: =IFERROR(SUMIF(PayRise!A:A,B26,PayRise!L:L),0) -> 0 | AH32: =IFERROR(AG32/BusinessCurrencyTRM,"N/A") -> N/A | AJ32: =IFERROR(SUMIF(PayRise!A:A,B26,PayRise!M:M),0) -> 0 | AK32: =IFERROR(AJ32/BusinessCurrencyTRM,"N/A") -> N/A | AN32: =SUM(AD32,AG32,AJ32) -> 0 | AO32: =IFERROR(AN32/BusinessCurrencyTRM,"N/A") -> N/A | AS32: Phase Price | AV32: =AN37 -> 6563.7381 | AW32: =IFERROR(AV32/BusinessCurrencyTRM,"N/A") -> N/A
N33: =IF(Approach="By Hours", "N/A for ByHours", "% Risks") -> N/A for ByHours | O33: 0 | U33: Products | V33: =IFERROR(SUMIFS(OtherCosts!Q:Q,OtherCosts!A:A,B26,OtherCosts!B:B,"Hardware/Software"),0) -> 0 | W33: =IFERROR(V33/BusinessCurrencyTRM,"N/A") -> N/A | Y33: varTotalProducts | AC33: Products | AD33: =IFERROR(SUMIFS(OtherCosts!R:R,OtherCosts!A:A,B26,OtherCosts!B:B,"Hardware/Software"),0) -> 0 | AE33: =IFERROR(AD33/BusinessCurrencyTRM,"N/A") -> N/A | AG33: =IFERROR(SUMIFS(OtherCosts!S:S,OtherCosts!A:A,B26,OtherCosts!B:B,"Hardware/Software"),0) -> 0 | AH33: =IFERROR(AG33/BusinessCurrencyTRM,"N/A") -> N/A | AJ33: =IFERROR(SUMIFS(OtherCosts!T:T,OtherCosts!A:A,B26,OtherCosts!B:B,"Hardware/Software"),0) -> 0 | AK33: =IFERROR(AJ33/BusinessCurrencyTRM,"N/A") -> N/A | AN33: =SUM(AD33,AG33,AJ33) -> 0 | AO33: =IFERROR(AN33/BusinessCurrencyTRM,"N/A") -> N/A | AS33: Monthly Price | AV33: =IFERROR(IF(O34<1,AN37,AN37/O34),0) -> 6563.7381 | AW33: =IFERROR(AV33/BusinessCurrencyTRM,"N/A") -> N/A
N34: =IF(Approach="By Hours", "N/A for ByHours", "Duration (Months) *") -> N/A for ByHours | O34: 0 | U34: Vendors | V34: =IFERROR(SUMIFS(OtherCosts!Q:Q,OtherCosts!A:A,B26,OtherCosts!B:B,"Vendor"),0) -> 0 | W34: =IFERROR(V34/BusinessCurrencyTRM,"N/A") -> N/A | Y34: varTotalVAR | AC34: Vendors | AD34: =IFERROR(SUMIFS(OtherCosts!R:R,OtherCosts!A:A,B26,OtherCosts!B:B,"Vendor"),0) -> 0 | AE34: =IFERROR(AD34/BusinessCurrencyTRM,"N/A") -> N/A | AG34: =IFERROR(SUMIFS(OtherCosts!S:S,OtherCosts!A:A,B26,OtherCosts!B:B,"Vendor"),0) -> 0 | AH34: =IFERROR(AG34/BusinessCurrencyTRM,"N/A") -> N/A | AJ34: =IFERROR(SUMIFS(OtherCosts!T:T,OtherCosts!A:A,B26,OtherCosts!B:B,"Vendor"),0) -> 0 | AK34: =IFERROR(AJ34/BusinessCurrencyTRM,"N/A") -> N/A | AN34: =SUM(AD34,AG34,AJ34) -> 0 | AO34: =IFERROR(AN34/BusinessCurrencyTRM,"N/A") -> N/A | AS34: Hour Price | AV34: =IFERROR(AN37/T40,0) -> 60.02504 | AW34: =IFERROR(AV34/BusinessCurrencyTRM,"N/A") -> N/A
U35: Insurances | V35: =IFERROR(SUMIFS(OtherCosts!Q:Q,OtherCosts!A:A,B26,OtherCosts!B:B,"Insurance"),0) -> 0 | W35: =IFERROR(V35/BusinessCurrencyTRM,"N/A") -> N/A | Y35: varTotalInsurances | AC35: Insurances | AD35: =IFERROR(SUMIFS(OtherCosts!R:R,OtherCosts!A:A,B26,OtherCosts!B:B,"Insurance"),0) -> 0 | AE35: =IFERROR(AD35/BusinessCurrencyTRM,"N/A") -> N/A | AG35: =IFERROR(SUMIFS(OtherCosts!S:S,OtherCosts!A:A,B26,OtherCosts!B:B,"Insurance"),0) -> 0 | AH35: =IFERROR(AG35/BusinessCurrencyTRM,"N/A") -> N/A | AJ35: =IFERROR(SUMIFS(OtherCosts!T:T,OtherCosts!A:A,B26,OtherCosts!B:B,"Insurance"),0) -> 0 | AK35: =IFERROR(AJ35/BusinessCurrencyTRM,"N/A") -> N/A | AN35: =SUM(AD35,AG35,AJ35) -> 0 | AO35: =IFERROR(AN35/BusinessCurrencyTRM,"N/A") -> N/A
U36: Others | V36: =IFERROR(SUMIFS(OtherCosts!Q:Q,OtherCosts!A:A,B26,OtherCosts!B:B,"Other"),0) -> 0 | W36: =IFERROR(V36/BusinessCurrencyTRM,"N/A") -> N/A | Y36: varTotalOthers | AC36: Others | AD36: =IFERROR(SUMIFS(OtherCosts!R:R,OtherCosts!A:A,B26,OtherCosts!B:B,"Other"),0) -> 0 | AE36: =IFERROR(AD36/BusinessCurrencyTRM,"N/A") -> N/A | AG36: =IFERROR(SUMIFS(OtherCosts!S:S,OtherCosts!A:A,B26,OtherCosts!B:B,"Other"),0) -> 0 | AH36: =IFERROR(AG36/BusinessCurrencyTRM,"N/A") -> N/A | AJ36: =IFERROR(SUMIFS(OtherCosts!T:T,OtherCosts!A:A,B26,OtherCosts!B:B,"Other"),0) -> 0 | AK36: =IFERROR(AJ36/BusinessCurrencyTRM,"N/A") -> N/A | AN36: =SUM(AD36,AG36,AJ36) -> 0 | AO36: =IFERROR(AN36/BusinessCurrencyTRM,"N/A") -> N/A
U37: Subtotal | V37: =SUM(V30:V36) -> 4200.632 | W37: =IFERROR(V37/BusinessCurrencyTRM,"N/A") -> N/A | AC37: Subtotal | AD37: =SUM(AD30:AD36) -> 6563.7381 | AE37: =IFERROR(AD37/BusinessCurrencyTRM,"N/A") -> N/A | AG37: =SUM(AG30:AG36) -> 0 | AH37: =IFERROR(AG37/BusinessCurrencyTRM,"N/A") -> N/A | AJ37: =SUM(AJ30:AJ36) -> 0 | AK37: =IFERROR(AJ37/BusinessCurrencyTRM,"N/A") -> N/A | AN37: =SUM(AD37,AG37,AJ37) -> 6563.7381 | AO37: =IFERROR(AN37/BusinessCurrencyTRM,"N/A") -> N/A
G40: =ROUNDUP(SUM(G42:G71),2) -> 82 | J40: =ROUNDUP(SUM(J42:J71),2) -> 91.12 | T40: =ROUNDUP(SUM(T42:T71),2) -> 109.35 | W40: =SUM(W42:W69) -> 4200.632 | Y40: varTotalFase | AD40: =SUM(AD42:AD71) -> 6563.7381 | AE40: =IFERROR(1-($W40/$AD40),0) -> 0.36002443 | AH40: =SUM(AH42:AH71) -> 0 | AK40: =ROUNDUP(SUM(AK42:AK71),2) -> 0 | AM40: =SUM(AM42:AM71) -> 6563.7381 | AN40: =SUM(AN42:AN71) -> 6563.7381 | AO40: =BillingCountryCurrency -> USD | AT40: =SUM(AT42:AU71) -> 6563.7381 | AV40: =BillingCountryCurrency -> USD | AW40: =IF(ISBLANK(BusinessCurrency),"N/A",BusinessCurrency) -> N/A
G41: Hours | H41: Risk | I41: EE | J41: Total | N41: Delivery Country | O41: Services Line | P41: Job Profile | Q41: Qty | R41: % Allocation | S41: Days | T41: Total Hours | U41: % Surcharge Hours | V41: Unit Cost Base | W41: Subtotal Cost | X41: FilterSL | Y41: FilterJP | AC41: Unit Price Base | AD41: Subtotal Price | AE41: % MaS | AG41: % Intercomp | AH41: $ Intercompany | AJ41: % WHT | AK41: $ WHT | AM41: Subtotal Price | AN41: Subtotal Price + Costs | AO41: Unit Price + Costs | AS41: Fact | AT41: Subtotal Price + Costs | AV41: Unit Price + Cost | AW41: Unit Price + Cost
B42: Observaciones / Incluido: | C42: • Pre-engagement | G42: 82 | H42: 0.1 | I42: 0 | J42: =IFERROR(G42/(1-(H42+I42)),0) -> 91.111111 | N42: xDC Medellin | O42: Cybersecurity | P42: Sr Expert Technology Implementation & Consulting (General) | S42: =IF(ISBLANK(P42),0,$O$34*20) -> 0 | T42: =J40 -> 91.12 | U42: 0 | V42: =ROUNDUP(IFERROR(INDEX(CostRateTbl[Cost Rate],MATCH(_xlfn.CONCAT(N42,O42,P42,"NA"),CostRateTbl[KeyCostRate],0)),0)*BillingCurrencyTRM*(1+U42),2) -> 36.62 | W42: =T42*V42 -> 3336.8144 | X42: {=_xlfn.LET( _xlpm.valor, INDEX(CostRate!H:H, MATCH(1, (CostRate!A:A=N42)*1, 0)), _xlpm.posicion, MATCH(_xlpm.valor, FilterSL!$F$1:$Z$1, 0), _xlpm.direccionCompleta, ADDRESS(1, _xlpm.posicion + 5, 4), _xlpm.letraColumna, SUBSTITUTE(_xlpm.direccionCompleta, "1", ""), _xlpm.letraColumna )} -> R | Y42: {=_xlfn.LET( _xlpm.valor, INDEX(CostRate!I:I, MATCH(1, (CostRate!A:A=N42)*(CostRate!B:B=O42), 0)), _xlpm.posicion, MATCH(_xlpm.valor, FilterJP!$E$1:$FZ$1, 0), _xlpm.direccionCompleta, ADDRESS(1, _xlpm.posicion + 4, 4), _xlpm.letraColumna, SUBSTITUTE(_xlpm.direccionCompleta, "1", ""), _xlpm.letraColumna )} -> BJ | AC42: =ROUNDUP($V42/(1-$AV$28),2) -> 57.22 | AD42: =$T42*$AC42 -> 5213.8864 | AE42: =IFERROR(1-($W42/$AD42),0) -> 0.36001398 | AG42: =IFERROR(IF(OR(ISBLANK(N42),N42=CustomerCountry,COUNTIF($N42,"*xDC*")),0,10%),0) -> 0 | AH42: =W42*AG42 -> 0 | AJ42: {=IFERROR(INDEX(WHT!$C$7:$W$18,MATCH( _xlfn.SWITCH(N42,"xDC Medellin","Colombia","xDC Belo Horizonte","Brazil","xDC Guadalajara","Mexico","xDC Gurugram","India","xDC Leon","Spain","xDC San Jose","Costa Rica","xDC Warsaw","Poland",N42), WHT!$B$7:$B$18,0),MATCH(CustomerCountry,WHT!$C$5:$W$5,0)),0)} -> 0 | AK42: =(W42+AH42)*AJ42 -> 0 | AM42: =SUM($AD42,$AH42,$AK42) -> 5213.8864 | AN42: =AM42+IFERROR(SUM($AN$31:$AN$36)*AM42/$AM$40,0) -> 5213.8864 | AO42: =IFERROR($AN42/$T42,0) -> 57.22 | AS42: X | AT42: =IF(AS42="x",AM42+((SUM($AN$31:$AN$36)+SUMIF($AS$42:$AS$71,"<>x",$AM$42:$AM$71))*IFERROR(AM42/SUMIF($AS$42:$AS$71,"x",$AM$42:$AM$71),0)),0) -> 5213.8864 | AV42: =IFERROR(AT42/T42,0) -> 57.22 | AW42: =IFERROR(AV42/BusinessCurrencyTRM,"N/A") -> N/A
C43: o Pre-engagement Call | H43: 0.1 | I43: 0 | J43: =IFERROR(G43/(1-(H43+I43)),0) -> 0
C44: o Prepare, Send and Review the Modern SecOps Envisioning Workshop Customer Questionnaire | G44: 0 | H44: 0.1 | I44: 0 | J44: =IFERROR(G44/(1-(H44+I44)),0) -> 0
C45: • Readiness (Optional) | G45: 0 | I45: 0 | J45: =IFERROR(G45/(1-(H45+I45)),0) -> 0
...

Sheet CMSCore 2.8
A1: Scope | N1: Delivery Cost - Internal Use | AC1: Price - Internal Use | AT1: Año 1 Ingreso Mensual | BA1: Año 2 Ingreso Mensual | BH1: Año 3 Ingreso Mensual | BO1: Año 4 Ingreso Mensual | BV1: Año 5 Ingreso Mensual
B2: Fields with * are mandatory for both DealReview and HandOff; ** denotes HandOff-only requirements | N2: Fields with * are mandatory for both DealReview and HandOff; ** denotes HandOff-only requirements
B3: Customer Country * | C3: Colombia | N3: Approach * | O3: Team-Based | U3: HOURS | V3: =_xlfn.CONCAT("DELIVERY COST (",BillingCountryCurrency,")") -> DELIVERY COST (COP) | W3: =_xlfn.CONCAT("DELIVERY COST (",IF(ISBLANK(BusinessCurrency),"N/A",BusinessCurrency),")") -> DELIVERY COST (USD) | AD3: =_xlfn.CONCAT("PRICING (",BillingCountryCurrency,")") -> PRICING (COP) | AE3: =_xlfn.CONCAT("PRICING (",IF(ISBLANK(BusinessCurrency),"N/A",BusinessCurrency),")") -> PRICING (USD) | AF3: + | AG3: =_xlfn.CONCAT("Intercompany (",BillingCountryCurrency,")") -> Intercompany (COP) | AH3: =_xlfn.CONCAT("Intercompany (",IF(ISBLANK(BusinessCurrency),"N/A",BusinessCurrency),")") -> Intercompany (USD) | AI3: + | AJ3: =_xlfn.CONCAT("WHT (",BillingCountryCurrency,")") -> WHT (COP) | AK3: =_xlfn.CONCAT("WHT (",IF(ISBLANK(BusinessCurrency),"N/A",BusinessCurrency),")") -> WHT (USD) | AM3: = | AN3: =_xlfn.CONCAT("BUSINESS VOLUME (",BillingCountryCurrency,")") -> BUSINESS VOLUME (COP) | AO3: =_xlfn.CONCAT("BUSINESS VOLUME (",IF(ISBLANK(BusinessCurrency),"N/A",BusinessCurrency),")") -> BUSINESS VOLUME (USD) | AS3: MILESTONES | AV3: =BillingCountryCurrency -> COP | AW3: =IF(ISBLANK(BusinessCurrency),"N/A",BusinessCurrency) -> USD | BA3: MILESTONES | BC3: =BillingCountryCurrency -> COP | BD3: =IF(ISBLANK(BusinessCurrency),"N/A",BusinessCurrency) -> USD | BH3: MILESTONES | BJ3: =BillingCountryCurrency -> COP | BK3: =IF(ISBLANK(BusinessCurrency),"N/A",BusinessCurrency) -> USD | BO3: MILESTONES | BQ3: =BillingCountryCurrency -> COP | BR3: =IF(ISBLANK(BusinessCurrency),"N/A",BusinessCurrency) -> USD | BV3: MILESTONES | BX3: =BillingCountryCurrency -> COP | BY3: =IF(ISBLANK(BusinessCurrency),"N/A",BusinessCurrency) -> USD
B4: Customer Name * | N4: =IF(Approach="By Hours", "N/A for ByHours", "Hours/Day") -> Hours/Day | O4: 8.1 | T4: SERVICE COSTS | AC4: SERVICE PRICE | AS4: Hito 1 | AU4: 0 | AV4: 0 | AW4: =IFERROR(AV4/BusinessCurrencyTRM,"N/A") -> 0 | BA4: Hito 1 | BB4: 0 | BC4: 0 | BD4: =IFERROR(BC4/BusinessCurrencyTRM,"N/A") -> 0 | BH4: Hito 1 | BI4: 0 | BJ4: 0 | BK4: =IFERROR(BJ4/BusinessCurrencyTRM,"N/A") -> 0 | BO4: Hito 1 | BP4: 0 | BQ4: 0 | BR4: =IFERROR(BQ4/BusinessCurrencyTRM,"N/A") -> 0 | BV4: Hito 1 | BW4: 0 | BX4: 0 | BY4: =IFERROR(BX4/BusinessCurrencyTRM,"N/A") -> 0
B5: Project Name * | T5: Consultant Team | U5: =IFERROR(SUMIFS(O:O,Y:Y,"varTotalConsultant"),0) -> 157.36583 | V5: =IFERROR(SUMIFS(V:V,Y:Y,"varTotalConsultant"),0) -> 6327455.9 | W5: =IFERROR(V5/BusinessCurrencyTRM,"N/A") -> 1622.4246 | AC5: Consultant Team | AD5: =IFERROR(SUMIF(Y:Y,"varTotalConsultant",AD:AD),0) -> 9039222.9 | AE5: =IFERROR(AD5/BusinessCurrencyTRM,"N/A") -> 2317.7495 | AG5: =IFERROR(SUMIF(Y:Y,"varTotalConsultant",AG:AG),0) -> 0 | AH5: =IFERROR(AG5/BusinessCurrencyTRM,"N/A") -> 0 | AJ5: =IFERROR(SUMIF(Y:Y,"varTotalConsultant",AJ:AJ),0) -> 0 | AK5: =IFERROR(AJ5/BusinessCurrencyTRM,"N/A") -> 0 | AN5: =SUM(AD5,AG5,AJ5) -> 9039222.9 | AO5: =IFERROR(AN5/BusinessCurrencyTRM,"N/A") -> 2317.7495 | AS5: Hito 2 | AU5: 0 | AV5: 0 | AW5: =IFERROR(AV5/BusinessCurrencyTRM,"N/A") -> 0 | BA5: Hito 2 | BB5: 0 | BC5: 0 | BD5: =IFERROR(BC5/BusinessCurrencyTRM,"N/A") -> 0 | BH5: Hito 2 | BI5: 0 | BJ5: 0 | BK5: =IFERROR(BJ5/BusinessCurrencyTRM,"N/A") -> 0 | BO5: Hito 2 | BP5: 0 | BQ5: 0 | BR5: =IFERROR(BQ5/BusinessCurrencyTRM,"N/A") -> 0 | BV5: Hito 2 | BW5: 0 | BX5: 0 | BY5: =IFERROR(BX5/BusinessCurrencyTRM,"N/A") -> 0
B6: Opp ID * | N6: Account Manager * | T6: Project Managment | U6: =IFERROR(SUMIFS(O:O,Y:Y,"varTotalPM"),0) -> 34.02 | V6: =IFERROR(SUMIFS(V:V,Y:Y,"varTotalPM"),0) -> 0 | W6: =IFERROR(V6/BusinessCurrencyTRM,"N/A") -> 0 | AC6: Project Managment | AD6: =IFERROR(SUMIF(Y:Y,"varTotalPM",AD:AD),0) -> 0 | AE6: =IFERROR(AD6/BusinessCurrencyTRM,"N/A") -> 0 | AG6: =IFERROR(SUMIF(Y:Y,"varTotalPM",AG:AG),0) -> 0 | AH6: =IFERROR(AG6/BusinessCurrencyTRM,"N/A") -> 0 | AJ6: =IFERROR(SUMIF(Y:Y,"varTotalPM",AJ:AJ),0) -> 0 | AK6: =IFERROR(AJ6/BusinessCurrencyTRM,"N/A") -> 0 | AN6: =SUM(AD6,AG6,AJ6) -> 0 | AO6: =IFERROR(AN6/BusinessCurrencyTRM,"N/A") -> 0 | AS6: Hito 3 | AU6: 0 | AV6: 0 | AW6: =IFERROR(AV6/BusinessCurrencyTRM,"N/A") -> 0 | BA6: Hito 3 | BB6: 0 | BC6: 0 | BD6: =IFERROR(BC6/BusinessCurrencyTRM,"N/A") -> 0 | BH6: Hito 3 | BI6: 0 | BJ6: 0 | BK6: =IFERROR(BJ6/BusinessCurrencyTRM,"N/A") -> 0 | BO6: Hito 3 | BP6: 0 | BQ6: 0 | BR6: =IFERROR(BQ6/BusinessCurrencyTRM,"N/A") -> 0 | BV6: Hito 3 | BW6: 0 | BX6: 0 | BY6: =IFERROR(BX6/BusinessCurrencyTRM,"N/A") -> 0
B7: SWO Job ID / PRJ | N7: Pre-sale in Sale * | T7: Subtotal | U7: =IFERROR(SUM(U5:U6),0) -> 191.38583 | V7: =IFERROR(SUM($V$5:$V$6),0) -> 6327455.9 | W7: =IFERROR(V7/BusinessCurrencyTRM,"N/A") -> 1622.4246 | AC7: Subtotal | AD7: =IFERROR(SUM(AD5:AD6),0) -> 9039222.9 | AE7: =IFERROR(AD7/BusinessCurrencyTRM,"N/A") -> 2317.7495 | AG7: =IFERROR(SUM(AG5:AG6),0) -> 0 | AH7: =IFERROR(AG7/BusinessCurrencyTRM,"N/A") -> 0 | AJ7: =IFERROR(SUM(AJ5:AJ6),0) -> 0 | AK7: =IFERROR(AJ7/BusinessCurrencyTRM,"N/A") -> 0 | AN7: =IFERROR(SUM(AN5:AN6),0) -> 9039222.9 | AO7: =IFERROR(AN7/BusinessCurrencyTRM,"N/A") -> 2317.7495 | AS7: Hito 4 | AU7: 0 | AV7: 0 | AW7: =IFERROR(AV7/BusinessCurrencyTRM,"N/A") -> 0 | BA7: Hito 4 | BB7: 0 | BC7: 0 | BD7: =IFERROR(BC7/BusinessCurrencyTRM,"N/A") -> 0 | BH7: Hito 4 | BI7: 0 | BJ7: 0 | BK7: =IFERROR(BJ7/BusinessCurrencyTRM,"N/A") -> 0 | BO7: Hito 4 | BP7: 0 | BQ7: 0 | BR7: =IFERROR(BQ7/BusinessCurrencyTRM,"N/A") -> 0 | BV7: Hito 4 | BW7: 0 | BX7: 0 | BY7: =IFERROR(BX7/BusinessCurrencyTRM,"N/A") -> 0
B8: Main Business Line * | C8: Cloud Services Azure | N8: Pre-sale in Delivery * | AS8: Hito 5 | AU8: 0 | AV8: 0 | AW8: =IFERROR(AV8/BusinessCurrencyTRM,"N/A") -> 0 | BA8: Hito 5 | BB8: 0 | BC8: 0 | BD8: =IFERROR(BC8/BusinessCurrencyTRM,"N/A") -> 0 | BH8: Hito 5 | BI8: 0 | BJ8: 0 | BK8: =IFERROR(BJ8/BusinessCurrencyTRM,"N/A") -> 0 | BO8: Hito 5 | BP8: 0 | BQ8: 0 | BR8: =IFERROR(BQ8/BusinessCurrencyTRM,"N/A") -> 0 | BV8: Hito 5 | BW8: 0 | BX8: 0 | BY8: =IFERROR(BX8/BusinessCurrencyTRM,"N/A") -> 0
B9: Funding * | C9: Customer | T9: OTHER COSTS | AC9: OTHER PRICES | AS9: Hito 6 | AU9: 0 | AV9: 0 | AW9: =IFERROR(AV9/BusinessCurrencyTRM,"N/A") -> 0 | BA9: Hito 6 | BB9: 0 | BC9: 0 | BD9: =IFERROR(BC9/BusinessCurrencyTRM,"N/A") -> 0 | BH9: Hito 6 | BI9: 0 | BJ9: 0 | BK9: =IFERROR(BJ9/BusinessCurrencyTRM,"N/A") -> 0 | BO9: Hito 6 | BP9: 0 | BQ9: 0 | BR9: =IFERROR(BQ9/BusinessCurrencyTRM,"N/A") -> 0 | BV9: Hito 6 | BW9: 0 | BX9: 0 | BY9: =IFERROR(BX9/BusinessCurrencyTRM,"N/A") -> 0
B10: OPP Type * | C10: New | N10: Billing Country * | O10: =CustomerCountry -> Colombia | T10: Risks | V10: =IFERROR(SUMIF(Y:Y,"varTotalRisks",V:V),0) -> 0 | W10: =IFERROR(V10/BusinessCurrencyTRM,"N/A") -> 0 | AC10: Risks | AD10: =IFERROR(SUMIF(Y:Y,"varTotalRisks",AD:AD),0) -> 0 | AE10: =IFERROR(AD10/BusinessCurrencyTRM,"N/A") -> 0 | AG10: =IFERROR(SUMIF(Y:Y,"varTotalRisks",AG:AG),0) -> 0 | AH10: =IFERROR(AG10/BusinessCurrencyTRM,"N/A") -> 0 | AJ10: =IFERROR(SUMIF(Y:Y,"varTotalRisks",AJ:AJ),0) -> 0 | AK10: =IFERROR(AJ10/BusinessCurrencyTRM,"N/A") -> 0 | AN10: =SUM(AD10,AG10,AJ10) -> 0 | AO10: =IFERROR(AN10/BusinessCurrencyTRM,"N/A") -> 0 | AS10: Hito 7 | AU10: 0 | AV10: 0 | AW10: =IFERROR(AV10/BusinessCurrencyTRM,"N/A") -> 0 | BA10: Hito 7 | BB10: 0 | BC10: 0 | BD10: =IFERROR(BC10/BusinessCurrencyTRM,"N/A") -> 0 | BH10: Hito 7 | BI10: 0 | BJ10: 0 | BK10: =IFERROR(BJ10/BusinessCurrencyTRM,"N/A") -> 0 | BO10: Hito 7 | BP10: 0 | BQ10: 0 | BR10: =IFERROR(BQ10/BusinessCurrencyTRM,"N/A") -> 0 | BV10: Hito 7 | BW10: 0 | BX10: 0 | BY10: =IFERROR(BX10/BusinessCurrencyTRM,"N/A") -> 0
N11: Billing Country Currency * | O11: =INDEX(Paramenters!$C$28:$C$85,MATCH(BillingCountry,Paramenters!$A$28:$A$85,0)) -> COP | T11: Pay Rise | V11: =IFERROR(SUMIF(Y:Y,"varTotalPayRise",V:V),0) -> 0 | W11: =IFERROR(V11/BusinessCurrencyTRM,"N/A") -> 0 | AC11: Salary Increase | AD11: =IFERROR(SUMIF(Y:Y,"varTotalPayRise",AD:AD),0) -> 0 | AE11: =IFERROR(AD11/BusinessCurrencyTRM,"N/A") -> 0 | AG11: =IFERROR(SUMIF(Y:Y,"varTotalPayRise",AG:AG),0) -> 0 | AH11: =IFERROR(AG11/BusinessCurrencyTRM,"N/A") -> 0 | AJ11: =IFERROR(SUMIF(Y:Y,"varTotalPayRise",AJ:AJ),0) -> 0 | AK11: =IFERROR(AJ11/BusinessCurrencyTRM,"N/A") -> 0 | AN11: =SUM(AD11,AG11,AJ11) -> 0 | AO11: =IFERROR(AN11/BusinessCurrencyTRM,"N/A") -> 0 | AS11: Hito 8 | AU11: 0 | AV11: 0 | AW11: =IFERROR(AV11/BusinessCurrencyTRM,"N/A") -> 0 | BA11: Hito 8 | BB11: 0 | BC11: 0 | BD11: =IFERROR(BC11/BusinessCurrencyTRM,"N/A") -> 0 | BH11: Hito 8 | BI11: 0 | BJ11: 0 | BK11: =IFERROR(BJ11/BusinessCurrencyTRM,"N/A") -> 0 | BO11: Hito 8 | BP11: 0 | BQ11: 0 | BR11: =IFERROR(BQ11/BusinessCurrencyTRM,"N/A") -> 0 | BV11: Hito 8 | BW11: 0 | BX11: 0 | BY11: =IFERROR(BX11/BusinessCurrencyTRM,"N/A") -> 0
B12: SKUs Business Line SWO * | C12: SKUs OneSales Descripcion * | T12: Products | V12: =IFERROR(SUMIF(Y:Y,"varTotalProducts",V:V),0) -> 0 | W12: =IFERROR(V12/BusinessCurrencyTRM,"N/A") -> 0 | AC12: Products | AD12: =IFERROR(SUMIF(Y:Y,"varTotalProducts",AD:AD),0) -> 0 | AE12: =IFERROR(AD12/BusinessCurrencyTRM,"N/A") -> 0 | AG12: =IFERROR(SUMIF(Y:Y,"varTotalProducts",AG:AG),0) -> 0 | AH12: =IFERROR(AG12/BusinessCurrencyTRM,"N/A") -> 0 | AJ12: =IFERROR(SUMIF(Y:Y,"varTotalProducts",AJ:AJ),0) -> 0 | AK12: =IFERROR(AJ12/BusinessCurrencyTRM,"N/A") -> 0 | AN12: =SUM(AD12,AG12,AJ12) -> 0 | AO12: =IFERROR(AN12/BusinessCurrencyTRM,"N/A") -> 0 | AS12: Hito 9 | AU12: 0 | AV12: 0 | AW12: =IFERROR(AV12/BusinessCurrencyTRM,"N/A") -> 0 | BA12: Hito 9 | BB12: 0 | BC12: 0 | BD12: =IFERROR(BC12/BusinessCurrencyTRM,"N/A") -> 0 | BH12: Hito 9 | BI12: 0 | BJ12: 0 | BK12: =IFERROR(BJ12/BusinessCurrencyTRM,"N/A") -> 0 | BO12: Hito 9 | BP12: 0 | BQ12: 0 | BR12: =IFERROR(BQ12/BusinessCurrencyTRM,"N/A") -> 0 | BV12: Hito 9 | BW12: 0 | BX12: 0 | BY12: =IFERROR(BX12/BusinessCurrencyTRM,"N/A") -> 0
N13: Business Currency | O13: USD | T13: Vendors | V13: =IFERROR(SUMIF(Y:Y,"varTotalVAR",V:V),0) -> 0 | W13: =IFERROR(V13/BusinessCurrencyTRM,"N/A") -> 0 | AC13: Vendors | AD13: =IFERROR(SUMIF(Y:Y,"varTotalVAR",AD:AD),0) -> 0 | AE13: =IFERROR(AD13/BusinessCurrencyTRM,"N/A") -> 0 | AG13: =IFERROR(SUMIF(Y:Y,"varTotalVAR",AG:AG),0) -> 0 | AH13: =IFERROR(AG13/BusinessCurrencyTRM,"N/A") -> 0 | AJ13: =IFERROR(SUMIF(Y:Y,"varTotalVAR",AJ:AJ),0) -> 0 | AK13: =IFERROR(AJ13/BusinessCurrencyTRM,"N/A") -> 0 | AN13: =SUM(AD13,AG13,AJ13) -> 0 | AO13: =IFERROR(AN13/BusinessCurrencyTRM,"N/A") -> 0 | AS13: Hito 10 | AU13: 0 | AV13: 0 | AW13: =IFERROR(AV13/BusinessCurrencyTRM,"N/A") -> 0 | BA13: Hito 10 | BB13: 0 | BC13: 0 | BD13: =IFERROR(BC13/BusinessCurrencyTRM,"N/A") -> 0 | BH13: Hito 10 | BI13: 0 | BJ13: 0 | BK13: =IFERROR(BJ13/BusinessCurrencyTRM,"N/A") -> 0 | BO13: Hito 10 | BP13: 0 | BQ13: 0 | BR13: =IFERROR(BQ13/BusinessCurrencyTRM,"N/A") -> 0 | BV13: Hito 10 | BW13: 0 | BX13: 0 | BY13: =IFERROR(BX13/BusinessCurrencyTRM,"N/A") -> 0
N14: Currency Exchange Rate | O14: 3900 | T14: Insurances | V14: =IFERROR(SUMIF(Y:Y,"varTotalInsurances",V:V),0) -> 0 | W14: =IFERROR(V14/BusinessCurrencyTRM,"N/A") -> 0 | AC14: Insurances | AD14: =IFERROR(SUMIF(Y:Y,"varTotalInsurances",AD:AD),0) -> 0 | AE14: =IFERROR(AD14/BusinessCurrencyTRM,"N/A") -> 0 | AG14: =IFERROR(SUMIF(Y:Y,"varTotalInsurances",AG:AG),0) -> 0 | AH14: =IFERROR(AG14/BusinessCurrencyTRM,"N/A") -> 0 | AJ14: =IFERROR(SUMIF(Y:Y,"varTotalInsurances",AJ:AJ),0) -> 0 | AK14: =IFERROR(AJ14/BusinessCurrencyTRM,"N/A") -> 0 | AN14: =SUM(AD14,AG14,AJ14) -> 0 | AO14: =IFERROR(AN14/BusinessCurrencyTRM,"N/A") -> 0 | AS14: Hito 11 | AU14: 0 | AV14: 0 | AW14: =IFERROR(AV14/BusinessCurrencyTRM,"N/A") -> 0 | BA14: Hito 11 | BB14: 0 | BC14: 0 | BD14: =IFERROR(BC14/BusinessCurrencyTRM,"N/A") -> 0 | BH14: Hito 11 | BI14: 0 | BJ14: 0 | BK14: =IFERROR(BJ14/BusinessCurrencyTRM,"N/A") -> 0 | BO14: Hito 11 | BP14: 0 | BQ14: 0 | BR14: =IFERROR(BQ14/BusinessCurrencyTRM,"N/A") -> 0 | BV14: Hito 11 | BW14: 0 | BX14: 0 | BY14: =IFERROR(BX14/BusinessCurrencyTRM,"N/A") -> 0
N15: Exchange Rate Request Date | O15: 45909 | T15: Others | V15: =IFERROR(SUMIF(Y:Y,"varTotalOthers",V:V),0) -> 0 | W15: =IFERROR(V15/BusinessCurrencyTRM,"N/A") -> 0 | AC15: Others | AD15: =IFERROR(SUMIF(Y:Y,"varTotalOthers",AD:AD),0) -> 0 | AE15: =IFERROR(AD15/BusinessCurrencyTRM,"N/A") -> 0 | AG15: =IFERROR(SUMIF(Y:Y,"varTotalOthers",AG:AG),0) -> 0 | AH15: =IFERROR(AG15/BusinessCurrencyTRM,"N/A") -> 0 | AJ15: =IFERROR(SUMIF(Y:Y,"varTotalOthers",AJ:AJ),0) -> 0 | AK15: =IFERROR(AJ15/BusinessCurrencyTRM,"N/A") -> 0 | AN15: =SUM(AD15,AG15,AJ15) -> 0 | AO15: =IFERROR(AN15/BusinessCurrencyTRM,"N/A") -> 0 | AS15: Hito 12 | AU15: 0 | AV15: 0 | AW15: =IFERROR(AV15/BusinessCurrencyTRM,"N/A") -> 0 | BA15: Hito 12 | BB15: 0 | BC15: 0 | BD15: =IFERROR(BC15/BusinessCurrencyTRM,"N/A") -> 0 | BH15: Hito 12 | BI15: 0 | BJ15: 0 | BK15: =IFERROR(BJ15/BusinessCurrencyTRM,"N/A") -> 0 | BO15: Hito 12 | BP15: 0 | BQ15: 0 | BR15: =IFERROR(BQ15/BusinessCurrencyTRM,"N/A") -> 0 | BV15: Hito 12 | BW15: 0 | BX15: 0 | BY15: =IFERROR(BX15/BusinessCurrencyTRM,"N/A") -> 0
O16: * Request the official TRM/RMR from the financial area and/or official url in each billing country. | T16: Subtotal | V16: =IFERROR(SUM(V10:V15),0) -> 0 | W16: =IFERROR(V16/BusinessCurrencyTRM,"N/A") -> 0 | AC16: Subtotal | AD16: =IFERROR(SUM(AD10:AD15),0) -> 0 | AE16: =IFERROR(AD16/BusinessCurrencyTRM,"N/A") -> 0 | AG16: =IFERROR(SUM(AG10:AG15),0) -> 0 | AH16: =IFERROR(AG16/BusinessCurrencyTRM,"N/A") -> 0 | AJ16: =IFERROR(SUM(AJ10:AJ15),0) -> 0 | AK16: =IFERROR(AJ16/BusinessCurrencyTRM,"N/A") -> 0 | AN16: =IFERROR(SUM(AN10:AN15),0) -> 0 | AO16: =IFERROR(AN16/BusinessCurrencyTRM,"N/A") -> 0 | AU16: =SUM(AU4:AU15) -> 0 | AV16: =SUM(AV4:AV15) -> 0 | AW16: =SUM(AW4:AW15) -> 0 | BB16: =SUM(BB4:BB15) -> 0 | BC16: =SUM(BC4:BC15) -> 0 | BD16: =SUM(BD4:BD15) -> 0 | BI16: =SUM(BI4:BI15) -> 0 | BJ16: =SUM(BJ4:BJ15) -> 0 | BK16: =SUM(BK4:BK15) -> 0 | BP16: =SUM(BP4:BP15) -> 0 | BQ16: =SUM(BQ4:BQ15) -> 0 | BR16: =SUM(BR4:BR15) -> 0 | BW16: =SUM(BW4:BW15) -> 0 | BX16: =SUM(BX4:BX15) -> 0 | BY16: =SUM(BY4:BY15) -> 0
B17: Deal Comments
B18: [WRITE COMMENTS THAT WERE TAKEN INTO ACCOUNT IN THE MODELING] | AV18: =BillingCountryCurrency -> COP | AW18: =IF(ISBLANK(BusinessCurrency),"N/A",BusinessCurrency) -> USD
AC19: SUBTOTAL | AD19: =SUM(AD7,AD16) -> 9039222.9 | AE19: =IFERROR(AD19/BusinessCurrencyTRM,"N/A") -> 2317.7495 | AG19: =SUM(AG7,AG16) -> 0 | AH19: =IFERROR(AG19/BusinessCurrencyTRM,"N/A") -> 0 | AJ19: =SUM(AJ7,AJ16) -> 0 | AK19: =IFERROR(AJ19/BusinessCurrencyTRM,"N/A") -> 0 | AN19: =SUM(AN7,AN16) -> 9039222.9 | AO19: =IFERROR(AN19/BusinessCurrencyTRM,"N/A") -> 2317.7495 | AS19: BUSINESS PRICE | AV19: =AN21 -> 9039222.9 | AW19: =IFERROR(AV19/BusinessCurrencyTRM,"N/A") -> 2317.7495
AC20: ADDITIONAL GP | AD20: 0 | AE20: =IFERROR(AD20/BusinessCurrencyTRM,"N/A") -> 0 | AG20: 0 | AH20: =IFERROR(AG20/BusinessCurrencyTRM,"N/A") -> 0 | AJ20: 0 | AK20: =IFERROR(AJ20/BusinessCurrencyTRM,"N/A") -> 0 | AN20: =SUM(AD20,AG20,AJ20) -> 0 | AO20: =IFERROR(AN20/BusinessCurrencyTRM,"N/A") -> 0 | AS20: DELIVERY COST | AV20: =SUM($V$21,$AG$21,$AJ$21) -> 6327455.9 | AW20: =IFERROR(AV20/BusinessCurrencyTRM,"N/A") -> 1622.4246
N21: =IF(CustomerCountry="Colombia","Impuesto de Timbre","") -> Impuesto de Timbre | O21: =IF(CustomerCountry="Colombia","Aplica a nuevos contratos donde la cuantia supera los 6.000 UVT (COP 298.794.000)","") -> Aplica a nuevos contratos donde la cuantia supera los 6.000 UVT (COP 298.794.000) | T21: TOTAL COSTS | V21: =V7+V16 -> 6327455.9 | W21: =IFERROR(V21/BusinessCurrencyTRM,"N/A") -> 1622.4246 | X21: =INDEX(Paramenters!$D$28:$D$85,MATCH(BillingCountryCurrency,Paramenters!$C$28:$C$85,0)) -> 4919.6912 | Y21: BillingCurrencyTRM | AC21: TOTAL PRICE | AD21: =SUM(AD19:AD20) -> 9039222.9 | AE21: =IFERROR(AD21/BusinessCurrencyTRM,"N/A") -> 2317.7495 | AG21: =SUM(AG19:AG20) -> 0 | AH21: =IFERROR(AG21/BusinessCurrencyTRM,"N/A") -> 0 | AJ21: =SUM(AJ19:AJ20) -> 0 | AK21: =IFERROR(AJ21/BusinessCurrencyTRM,"N/A") -> 0 | AN21: =SUM(AN19:AN20) -> 9039222.9 | AO21: =IFERROR(AN21/BusinessCurrencyTRM,"N/A") -> 2317.7495 | AS21: % CONTRIBUTION MARGIN | AV21: =IFERROR(1-AV20/AV19,0) -> 0.30000001
B24: (Note 1) To add new phases/stages/blocks, it is recommended to use the phase/stage/block called "Phase_Name_7" which does not have fixed references and allows maintaining cell relationships.
B26: Equipo de Trabajo - Plantilla
N27: PROJECT WEIGHT BY PHASE | O27: Hours | P27: Percentage (%) | U27: COSTS BY PHASE | V27: =_xlfn.CONCAT("DELIVERY COST (",BillingCountryCurrency,")") -> DELIVERY COST (COP) | W27: =_xlfn.CONCAT("DELIVERY COST (",IF(ISBLANK(BusinessCurrency),"N/A",BusinessCurrency),")") -> DELIVERY COST (USD) | AC27: PRICE BY PHASE | AD27: =_xlfn.CONCAT("PRICING (",BillingCountryCurrency,")") -> PRICING (COP) | AE27: =_xlfn.CONCAT("PRICING (",IF(ISBLANK(BusinessCurrency),"N/A",BusinessCurrency),")") -> PRICING (USD) | AF27: + | AG27: =_xlfn.CONCAT("Intercompany (",BillingCountryCurrency,")") -> Intercompany (COP) | AH27: =_xlfn.CONCAT("Intercompany (",IF(ISBLANK(BusinessCurrency),"N/A",BusinessCurrency),")") -> Intercompany (USD) | AI27: + | AJ27: =_xlfn.CONCAT("WHT (",BillingCountryCurrency,")") -> WHT (COP) | AK27: =_xlfn.CONCAT("WHT (",IF(ISBLANK(BusinessCurrency),"N/A",BusinessCurrency),")") -> WHT (USD) | AM27: = | AN27: =_xlfn.CONCAT("SUBTOTAL PRICE (",BillingCountryCurrency,")") -> SUBTOTAL PRICE (COP) | AO27: =_xlfn.CONCAT("SUBTOTAL PRICE (",IF(ISBLANK(BusinessCurrency),"N/A",BusinessCurrency),")") -> SUBTOTAL PRICE (USD) | AS27: SUMMARY BY PHASE
N28: Consultant Team: | O28: =SUMIF($P42:$P71,"<>*Project Management*",$T42:$T71) -> 26.227638 | P28: =IFERROR(O28/O31,0) -> 0.82224389 | U28: Consultant Team | V28: =SUMIF(P42:P71,"<>*Project Management*",W42:W71) -> 1061346.2 | W28: =IFERROR(V28/BusinessCurrencyTRM,"N/A") -> 272.14005 | Y28: varTotalConsultant | AC28: Consultant Team | AD28: =SUMIF(P42:P71,"<>*Project Management*",AD42:AD71) -> 1516208.9 | AE28: =IFERROR(AD28/BusinessCurrencyTRM,"N/A") -> 388.7715 | AG28: =SUMIF(P42:P71,"<>*Project Management*",AH42:AH71) -> 0 | AH28: =IFERROR(AG28/BusinessCurrencyTRM,"N/A") -> 0 | AJ28: =SUMIF(P42:P71,"<>*Project Management*",AK42:AK71) -> 0 | AK28: =IFERROR(AJ28/BusinessCurrencyTRM,"N/A") -> 0 | AN28: =SUM(AD28,AG28,AJ28) -> 1516208.9 | AO28: =IFERROR(AN28/BusinessCurrencyTRM,"N/A") -> 388.7715 | AS28: % Margin a Sold * | AV28: =CMSResumen!H21 -> 0.3
N29: Project Managment: | O29: =SUMIF($P42:$P71,"=*Project Management*",$T42:T71) -> 5.67 | P29: =IFERROR(O29/O31,0) -> 0.17775611 | U29: Project Managment | V29: =SUMIF(P42:P71,"=*Project Management*",W42:W71) -> 0 | W29: =IFERROR(V29/BusinessCurrencyTRM,"N/A") -> 0 | Y29: varTotalPM | AC29: Project Managment | AD29: =SUMIF(P42:P71,"=*Project Management*",AD42:AD71) -> 0 | AE29: =IFERROR(AD29/BusinessCurrencyTRM,"N/A") -> 0 | AG29: =SUMIF(P42:P71,"=*Project Management*",AH42:AH71) -> 0 | AH29: =IFERROR(AG29/BusinessCurrencyTRM,"N/A") -> 0 | AJ29: =SUMIF(P42:P71,"=*Project Management*",AK42:AK71) -> 0 | AK29: =IFERROR(AJ29/BusinessCurrencyTRM,"N/A") -> 0 | AN29: =SUM(AD29,AG29,AJ29) -> 0 | AO29: =IFERROR(AN29/BusinessCurrencyTRM,"N/A") -> 0 | AS29: % Contribution Margin | AV29: =IFERROR(1-AV31/AV32,0) -> 0.30000001
N30: Risk / Extra Effort: | O30: =IF(Approach="Team-Based",SUM(O28:O29)*$O33,$J40-$G40) -> 0 | P30: =IFERROR(O30/O31,0) -> 0 | U30: Subtotal | V30: =SUM(V28:V29) -> 1061346.2 | W30: =IFERROR(V30/BusinessCurrencyTRM,"N/A") -> 272.14005 | AC30: Subtotal | AD30: =SUM(AD28:AD29) -> 1516208.9 | AE30: =IFERROR(AD30/BusinessCurrencyTRM,"N/A") -> 388.7715 | AG30: =SUM(AG28:AG29) -> 0 | AH30: =IFERROR(AG30/BusinessCurrencyTRM,"N/A") -> 0 | AJ30: =SUM(AJ28:AJ29) -> 0 | AK30: =IFERROR(AJ30/BusinessCurrencyTRM,"N/A") -> 0 | AN30: =SUM(AD30,AG30,AJ30) -> 1516208.9 | AO30: =IFERROR(AN30/BusinessCurrencyTRM,"N/A") -> 388.7715 | AV30: =BillingCountryCurrency -> COP | AW30: =IF(ISBLANK(BusinessCurrency),"N/A",BusinessCurrency) -> USD
N31: Total | O31: =SUM(O28:O30) -> 31.897638 | P31: =SUM(P28:P30) -> 1 | U31: Risks | V31: =ROUNDUP(V30*O33,2) -> 0 | W31: =IFERROR(V31/BusinessCurrencyTRM,"N/A") -> 0 | Y31: varTotalRisks | AC31: Risks | AD31: =ROUNDUP(V31/(1-$AV$28),2) -> 0 | AE31: =IFERROR(AD31/BusinessCurrencyTRM,"N/A") -> 0 | AG31: =IFERROR(V31*MAX(AG42:AG71),0) -> 0 | AH31: =IFERROR(AG31/BusinessCurrencyTRM,"N/A") -> 0 | AJ31: =IFERROR(SUM(V31,AG31)*MAX(AJ42:AJ71),0) -> 0 | AK31: =IFERROR(AJ31/BusinessCurrencyTRM,"N/A") -> 0 | AN31: =SUM(AD31,AG31,AJ31) -> 0 | AO31: =IFERROR(AN31/BusinessCurrencyTRM,"N/A") -> 0 | AS31: Phase Cost | AV31: =SUM(V37,AG37,AJ37) -> 1061346.2 | AW31: =IFERROR(AV31/BusinessCurrencyTRM,"N/A") -> 272.14005
U32: Pay Rise | V32: =IFERROR(SUMIF(PayRise!A:A,B26,PayRise!J:J),0) -> 0 | W32: =IFERROR(V32/BusinessCurrencyTRM,"N/A") -> 0 | Y32: varTotalPayRise | AC32: Pay Rise | AD32: =IFERROR(SUMIF(PayRise!A:A,B26,PayRise!K:K),0) -> 0 | AE32: =IFERROR(AD32/BusinessCurrencyTRM,"N/A") -> 0 | AG32: =IFERROR(SUMIF(PayRise!A:A,B26,PayRise!L:L),0) -> 0 | AH32: =IFERROR(AG32/BusinessCurrencyTRM,"N/A") -> 0 | AJ32: =IFERROR(SUMIF(PayRise!A:A,B26,PayRise!M:M),0) -> 0 | AK32: =IFERROR(AJ32/BusinessCurrencyTRM,"N/A") -> 0 | AN32: =SUM(AD32,AG32,AJ32) -> 0 | AO32: =IFERROR(AN32/BusinessCurrencyTRM,"N/A") -> 0 | AS32: Phase Price | AV32: =AN37 -> 1516208.9 | AW32: =IFERROR(AV32/BusinessCurrencyTRM,"N/A") -> 388.7715
N33: =IF(Approach="By Hours", "N/A for ByHours", "% Risks") -> % Risks | O33: 0 | U33: Products | V33: =IFERROR(SUMIFS(OtherCosts!Q:Q,OtherCosts!A:A,B26,OtherCosts!B:B,"Hardware/Software"),0) -> 0 | W33: =IFERROR(V33/BusinessCurrencyTRM,"N/A") -> 0 | Y33: varTotalProducts | AC33: Products | AD33: =IFERROR(SUMIFS(OtherCosts!R:R,OtherCosts!A:A,B26,OtherCosts!B:B,"Hardware/Software"),0) -> 0 | AE33: =IFERROR(AD33/BusinessCurrencyTRM,"N/A") -> 0 | AG33: =IFERROR(SUMIFS(OtherCosts!S:S,OtherCosts!A:A,B26,OtherCosts!B:B,"Hardware/Software"),0) -> 0 | AH33: =IFERROR(AG33/BusinessCurrencyTRM,"N/A") -> 0 | AJ33: =IFERROR(SUMIFS(OtherCosts!T:T,OtherCosts!A:A,B26,OtherCosts!B:B,"Hardware/Software"),0) -> 0 | AK33: =IFERROR(AJ33/BusinessCurrencyTRM,"N/A") -> 0 | AN33: =SUM(AD33,AG33,AJ33) -> 0 | AO33: =IFERROR(AN33/BusinessCurrencyTRM,"N/A") -> 0 | AS33: Monthly Price | AV33: =IFERROR(IF(O34<1,AN37,AN37/O34),0) -> 1516208.9 | AW33: =IFERROR(AV33/BusinessCurrencyTRM,"N/A") -> 388.7715
N34: =IF(Approach="By Hours", "N/A for ByHours", "Duration (Months) *") -> Duration (Months) * | O34: 1 | U34: Vendors | V34: =IFERROR(SUMIFS(OtherCosts!Q:Q,OtherCosts!A:A,B26,OtherCosts!B:B,"Vendor"),0) -> 0 | W34: =IFERROR(V34/BusinessCurrencyTRM,"N/A") -> 0 | Y34: varTotalVAR | AC34: Vendors | AD34: =IFERROR(SUMIFS(OtherCosts!R:R,OtherCosts!A:A,B26,OtherCosts!B:B,"Vendor"),0) -> 0 | AE34: =IFERROR(AD34/BusinessCurrencyTRM,"N/A") -> 0 | AG34: =IFERROR(SUMIFS(OtherCosts!S:S,OtherCosts!A:A,B26,OtherCosts!B:B,"Vendor"),0) -> 0 | AH34: =IFERROR(AG34/BusinessCurrencyTRM,"N/A") -> 0 | AJ34: =IFERROR(SUMIFS(OtherCosts!T:T,OtherCosts!A:A,B26,OtherCosts!B:B,"Vendor"),0) -> 0 | AK34: =IFERROR(AJ34/BusinessCurrencyTRM,"N/A") -> 0 | AN34: =SUM(AD34,AG34,AJ34) -> 0 | AO34: =IFERROR(AN34/BusinessCurrencyTRM,"N/A") -> 0 | AS34: Hour Price | AV34: =IFERROR(AN37/T40,0) -> 47530.058 | AW34: =IFERROR(AV34/BusinessCurrencyTRM,"N/A") -> 12.187194
U35: Insurances | V35: =IFERROR(SUMIFS(OtherCosts!Q:Q,OtherCosts!A:A,B26,OtherCosts!B:B,"Insurance"),0) -> 0 | W35: =IFERROR(V35/BusinessCurrencyTRM,"N/A") -> 0 | Y35: varTotalInsurances | AC35: Insurances | AD35: =IFERROR(SUMIFS(OtherCosts!R:R,OtherCosts!A:A,B26,OtherCosts!B:B,"Insurance"),0) -> 0 | AE35: =IFERROR(AD35/BusinessCurrencyTRM,"N/A") -> 0 | AG35: =IFERROR(SUMIFS(OtherCosts!S:S,OtherCosts!A:A,B26,OtherCosts!B:B,"Insurance"),0) -> 0 | AH35: =IFERROR(AG35/BusinessCurrencyTRM,"N/A") -> 0 | AJ35: =IFERROR(SUMIFS(OtherCosts!T:T,OtherCosts!A:A,B26,OtherCosts!B:B,"Insurance"),0) -> 0 | AK35: =IFERROR(AJ35/BusinessCurrencyTRM,"N/A") -> 0 | AN35: =SUM(AD35,AG35,AJ35) -> 0 | AO35: =IFERROR(AN35/BusinessCurrencyTRM,"N/A") -> 0
U36: Others | V36: =IFERROR(SUMIFS(OtherCosts!Q:Q,OtherCosts!A:A,B26,OtherCosts!B:B,"Other"),0) -> 0 | W36: =IFERROR(V36/BusinessCurrencyTRM,"N/A") -> 0 | Y36: varTotalOthers | AC36: Others | AD36: =IFERROR(SUMIFS(OtherCosts!R:R,OtherCosts!A:A,B26,OtherCosts!B:B,"Other"),0) -> 0 | AE36: =IFERROR(AD36/BusinessCurrencyTRM,"N/A") -> 0 | AG36: =IFERROR(SUMIFS(OtherCosts!S:S,OtherCosts!A:A,B26,OtherCosts!B:B,"Other"),0) -> 0 | AH36: =IFERROR(AG36/BusinessCurrencyTRM,"N/A") -> 0 | AJ36: =IFERROR(SUMIFS(OtherCosts!T:T,OtherCosts!A:A,B26,OtherCosts!B:B,"Other"),0) -> 0 | AK36: =IFERROR(AJ36/BusinessCurrencyTRM,"N/A") -> 0 | AN36: =SUM(AD36,AG36,AJ36) -> 0 | AO36: =IFERROR(AN36/BusinessCurrencyTRM,"N/A") -> 0
U37: Subtotal | V37: =SUM(V30:V36) -> 1061346.2 | W37: =IFERROR(V37/BusinessCurrencyTRM,"N/A") -> 272.14005 | AC37: Subtotal | AD37: =SUM(AD30:AD36) -> 1516208.9 | AE37: =IFERROR(AD37/BusinessCurrencyTRM,"N/A") -> 388.7715 | AG37: =SUM(AG30:AG36) -> 0 | AH37: =IFERROR(AG37/BusinessCurrencyTRM,"N/A") -> 0 | AJ37: =SUM(AJ30:AJ36) -> 0 | AK37: =IFERROR(AJ37/BusinessCurrencyTRM,"N/A") -> 0 | AN37: =SUM(AD37,AG37,AJ37) -> 1516208.9 | AO37: =IFERROR(AN37/BusinessCurrencyTRM,"N/A") -> 388.7715
G40: =ROUNDUP(SUM(G42:G71),2) -> 0 | J40: =ROUNDUP(SUM(J42:J71),2) -> 0 | T40: =ROUNDUP(SUM(T42:T71),2) -> 31.9 | W40: =SUM(W42:W69) -> 1061346.2 | Y40: varTotalFase | AD40: =SUM(AD42:AD71) -> 1516208.9 | AE40: =IFERROR(1-($W40/$AD40),0) -> 0.30000001 | AH40: =SUM(AH42:AH71) -> 0 | AK40: =ROUNDUP(SUM(AK42:AK71),2) -> 0 | AM40: =SUM(AM42:AM71) -> 1516208.9 | AN40: =SUM(AN42:AN71) -> 1516208.9 | AO40: =BillingCountryCurrency -> COP | AT40: =SUM(AT42:AU71) -> 1516208.9 | AV40: =BillingCountryCurrency -> COP | AW40: =IF(ISBLANK(BusinessCurrency),"N/A",BusinessCurrency) -> USD
G41: Hours | H41: Risk | I41: EE | J41: Total | N41: Delivery Country | O41: Services Line | P41: Job Profile | Q41: Qty | R41: % Allocation | S41: Days | T41: Total Hours | U41: % Surcharge Hours | V41: Unit Cost Base | W41: Subtotal Cost | X41: FilterSL | Y41: FilterJP | AC41: Unit Price Base | AD41: Subtotal Price | AE41: % MaS | AG41: % Intercomp | AH41: $ Intercompany | AJ41: % WHT | AK41: $ WHT | AM41: Subtotal Price | AN41: Subtotal Price + Costs | AO41: Unit Price + Costs | AS41: Fact | AT41: Subtotal Price + Costs | AV41: Unit Price + Cost | AW41: Unit Price + Cost
B42: Observaciones / Incluido: | C42: Gerencia del proyecto | G42: 0 | H42: 0 | I42: 0 | J42: =IFERROR(G42/(1-(H42+I42)),0) -> 0 | N42: xDC Medellin | O42: Other Services | P42: Expert Technology & Consulting Project Management | Q42: 1 | R42: 0.035 | S42: 20 | T42: =IF(ISBLANK($P42),0,IF(Approach="Team-Based",$Q42*$R42*$S42*HoursPerDayTeamBased,$J42)) -> 5.67 | U42: 0 | V42: =ROUNDUP(IFERROR(INDEX(CostRateTbl[Cost Rate],MATCH(_xlfn.CONCAT(N42,O42,P42,"NA"),CostRateTbl[KeyCostRate],0)),0)*BillingCurrencyTRM*(1+U42),2) -> 0 | W42: =T42*V42 -> 0 | X42: {=_xlfn.LET( _xlpm.valor, INDEX(CostRate!H:H, MATCH(1, (CostRate!A:A=N42)*1, 0)), _xlpm.posicion, MATCH(_xlpm.valor, FilterSL!$F$1:$Z$1, 0), _xlpm.direccionCompleta, ADDRESS(1, _xlpm.posicion + 5, 4), _xlpm.letraColumna, SUBSTITUTE(_xlpm.direccionCompleta, "1", ""), _xlpm.letraColumna )} -> R | Y42: {=_xlfn.LET( _xlpm.valor, INDEX(CostRate!I:I, MATCH(1, (CostRate!A:A=N42)*(CostRate!B:B=O42), 0)), _xlpm.posicion, MATCH(_xlpm.valor, FilterJP!$E$1:$FZ$1, 0), _xlpm.direccionCompleta, ADDRESS(1, _xlpm.posicion + 4, 4), _xlpm.letraColumna, SUBSTITUTE(_xlpm.direccionCompleta, "1", ""), _xlpm.letraColumna )} -> BO | AC42: =ROUNDUP($V42/(1-$AV$28),2) -> 0 | AD42: =$T42*$AC42 -> 0 | AE42: =IFERROR(1-($W42/$AD42),0) -> 0 | AG42: =IFERROR(IF(OR(ISBLANK(N42),N42=CustomerCountry,COUNTIF($N42,"*xDC*")),0,10%),0) -> 0 | AH42: =W42*AG42 -> 0 | AJ42: {=IFERROR(INDEX(WHT!$C$7:$W$18,MATCH( _xlfn.SWITCH(N42,"xDC Medellin","Colombia","xDC Belo Horizonte","Brazil","xDC Guadalajara","Mexico","xDC Gurugram","India","xDC Leon","Spain","xDC San Jose","Costa Rica","xDC Warsaw","Poland",N42), WHT!$B$7:$B$18,0),MATCH(CustomerCountry,WHT!$C$5:$W$5,0)),0)} -> 0 | AK42: =(W42+AH42)*AJ42 -> 0 | AM42: =SUM($AD42,$AH42,$AK42) -> 0 | AN42: =AM42+IFERROR(SUM($AN$31:$AN$36)*AM42/$AM$40,0) -> 0 | AO42: =IFERROR($AN42/$T42,0) -> 0 | AS42: X | AT42: =IF(AS42="x",AM42+((SUM($AN$31:$AN$36)+SUMIF($AS$42:$AS$71,"<>x",$AM$42:$AM$71))*IFERROR(AM42/SUMIF($AS$42:$AS$71,"x",$AM$42:$AM$71),0)),0) -> 0 | AV42: =IFERROR(AT42/T42,0) -> 0 | AW42: =IFERROR(AV42/BusinessCurrencyTRM,"N/A") -> 0
